Workbook

Sheet CALCULADORA
A1: CALCULADORA DE TARIFAS DE TRANSPORTE DE GAS - SNT
A4: 1. SELECCIONE LA RUTA Y LAS OPCIONES
A5: Origen | C5: Jobo | T5: =C5
A6: Destino | C6: Ballenas_prom | T6: =C6
A7: Opcion %CF (Fijo/Variable) | C7: 0% Fijo / 100% Variable | T7: =VLOOKUP(C7,listas!$D$2:$E$8,2,0)
A8: TRM (COP por USD) | C8: 4000 | T8: =C8
A9: Impuesto local TGI | C9: 6% - Impuesto especial municipal | E9: Impuesto local y cuota de fomento de arriba aplican SOLO A TGI. PROMIGAS se liquida automaticamente con 3% de cuota de fomento y 6% de impuesto local (no editables). | T9: =VLOOKUP(C9,listas!$G$2:$H$4,2,0)
A10: Cuota de fomento TGI | C10: 0.03 | T10: =C10
A12: 2. RUTA CALCULADA
A13: Tipo de ruta: | C13: =Calculo!B18&IF(Calculo!B19="-",""," / "&Calculo!B19)
A14: Tramos utilizados: | C14: =Calculo!B71
A16: 3. DESGLOSE POR TRANSPORTADOR (cada uno liquida su estampilla, su fomento y su impuesto)
A17: Transportador | B17: Usa | C17: Fijos pond. | D17: Variables pond. | E17: AOM | F17: Estampilla | G17: Base | H17: % Fomento | I17: Fomento | J17: % Impuesto | K17: Impuesto | L17: Total
A18: TGI (editable) | B18: =Calculo!B57 | C18: =Calculo!C57 | D18: =Calculo!D57 | E18: =Calculo!E57 | F18: =Calculo!F57 | G18: =Calculo!G57 | H18: =Calculo!H57 | I18: =Calculo!I57 | ... L18: =Calculo!L57
A19: PROMIGAS (automatico) | B19: =Calculo!B58 | C19: =Calculo!C58 | D19: =Calculo!D58 | E19: =Calculo!E58 | F19: =Calculo!F58 | G19: =Calculo!G58 | H19: =Calculo!H58 | I19: =Calculo!I58 | ... L19: =Calculo!L58
A20: TOTALES | C20: =Calculo!C59 | D20: =Calculo!D59 | E20: =Calculo!E59 | F20: =Calculo!F59 | G20: =Calculo!G59 | I20: =Calculo!I59 | K20: =Calculo!K59 | L20: =Calculo!L59
A22: 4. RESULTADO FINAL
A23: Costo base transporte (COP/KPC) | E23: =Calculo!B64
A24: Cuota de fomento - suma transportadores (COP/KPC) | E24: =Calculo!B65
A25: Impuesto local - suma transportadores (COP/KPC) | E25: =Calculo!B66
A26: TOTAL (COP/KPC) | E26: =Calculo!B67
A27: Costo base transporte (USD/KPC) | E27: =Calculo!B68
A28: TOTAL (USD/KPC) | E28: =Calculo!B69
A31: Notas: %CF = porcentaje que se cobra como cargo fijo (el resto se cobra como cargo variable); el AOM se cobra 100% independiente del %CF. La estampilla se cobra una sola vez por transportador usado en la ruta. Si Origen y Destino estan en redes distintas, la ruta es COMBINADA: se suma la ruta del Origen hasta el punto de entrada de su red y la del punto de entrada de la red del Destino hasta el Destino, y se cobran las estampillas, cuotas de fomento e impuestos de ambos transportadores. La cuota de fomento y el impuesto local se liquidan POR TRANSPORTADOR sobre su propia base (sus tramos + su estampilla): TGI usa los porcentajes editables de arriba; PROMIGAS usa 3% y 6% fijos, que se cambian en Calculo!B10 y Calculo!B11. Fuente de tarifas: hoja TRAMOS.

Sheet Calculo
A1: MOTOR DE CALCULO - no editar (alimenta la hoja CALCULADORA)
A3: PARAMETROS DE ENTRADA
A4: Origen | B4: =CALCULADORA!T5
A5: Destino | B5: =CALCULADORA!T6
A6: %CF (fraccion Fijo) | B6: =CALCULADORA!T7
A7: TRM (COP/USD) | B7: =CALCULADORA!T8
A8: % Impuesto local TGI (editable) | B8: =CALCULADORA!T9
A9: % Cuota de fomento TGI (editable) | B9: =CALCULADORA!T10
A10: % Cuota de fomento PROMIGAS (fijo) | B10: 0.03
A11: % Impuesto local PROMIGAS (fijo) | B11: 0.06
A13: VALIDACION DE RUTA
A14: Fila de Origen en matriz | B14: =MATCH(B4,$A$76:$A$109,0)
A15: Fila de Destino en matriz | B15: =MATCH(B5,$A$76:$A$109,0)
A16: Red de Origen | B16: =INDEX($B$76:$B$109,B14)
A17: Red de Destino | B17: =INDEX($B$76:$B$109,B15)
A18: Ruta valida? | B18: =IF(B4=B5,"ORIGEN = DESTINO","SI")
A19: Tipo de ruta | B19: =IF($B$18<>"SI","-",IF($B$16=$B$17,"DIRECTA","COMBINADA - se suman las dos rutas hasta el punto de entrada de cada red"))
A20: Tramo | B20: Ruta | C20: Transportador | D20: Fijos | E20: Variables | F20: AOM | G20: Incluido | H20: Fijo ponderado | I20: Variable ponderado | J20: AOM incluido
A21: =TRAMOS!J2 | B21: =TRAMOS!A2 | C21: =TRAMOS!I2 | D21: =TRAMOS!D2 | E21: =TRAMOS!E2 | F21: =TRAMOS!F2 | G21: =IF($B$18<>"SI",0,IF($B$16=$B$17,ABS(INDEX($C$76:$AH$109,$B$14,1)-INDEX($C$76:$AH$109,$B$15,1)),INDEX($C$76:$AH$109,$B$14,1)+INDEX($C$76:$AH$109,$B$15,1))) | H21: =D21*$B$6*G21 | I21: =E21*(1-$B$6)*G21 | J21: =F21*G21
A22: =TRAMOS!J3 | B22: =TRAMOS!A3 | C22: =TRAMOS!I3 | D22: =TRAMOS!D3 | E22: =TRAMOS!E3 | F22: =TRAMOS!F3 | G22: =IF($B$18<>"SI",0,IF($B$16=$B$17,ABS(INDEX($C$76:$AH$109,$B$14,2)-INDEX($C$76:$AH$109,$B$15,2)),INDEX($C$76:$AH$109,$B$14,2)+INDEX($C$76:$AH$109,$B$15,2))) | H22: =D22*$B$6*G22 | I22: =E22*(1-$B$6)*G22 | J22: =F22*G22
A23: =TRAMOS!J4 | B23: =TRAMOS!A4 | C23: =TRAMOS!I4 | D23: =TRAMOS!D4 | E23: =TRAMOS!E4 | F23: =TRAMOS!F4 | G23: =IF($B$18<>"SI",0,IF($B$16=$B$17,ABS(INDEX($C$76:$AH$109,$B$14,3)-INDEX($C$76:$AH$109,$B$15,3)),INDEX($C$76:$AH$109,$B$14,3)+INDEX($C$76:$AH$109,$B$15,3))) | H23: =D23*$B$6*G23 | I23: =E23*(1-$B$6)*G23 | J23: =F23*G23
A24: =TRAMOS!J5 | B24: =TRAMOS!A5 | C24: =TRAMOS!I5 | D24: =TRAMOS!D5 | E24: =TRAMOS!E5 | F24: =TRAMOS!F5 | G24: =IF($B$18<>"SI",0,IF($B$16=$B$17,ABS(INDEX($C$76:$AH$109,$B$14,4)-INDEX($C$76:$AH$109,$B$15,4)),INDEX($C$76:$AH$109,$B$14,4)+INDEX($C$76:$AH$109,$B$15,4))) | H24: =D24*$B$6*G24 | I24: =E24*(1-$B$6)*G24 | J24: =F24*G24
A25: =TRAMOS!J6 | B25: =TRAMOS!A6 | C25: =TRAMOS!I6 | D25: =TRAMOS!D6 | E25: =TRAMOS!E6 | F25: =TRAMOS!F6 | G25: =IF($B$18<>"SI",0,IF($B$16=$B$17,ABS(INDEX($C$76:$AH$109,$B$14,5)-INDEX($C$76:$AH$109,$B$15,5)),INDEX($C$76:$AH$109,$B$14,5)+INDEX($C$76:$AH$109,$B$15,5))) | H25: =D25*$B$6*G25 | I25: =E25*(1-$B$6)*G25 | J25: =F25*G25
A26: =TRAMOS!J7 | B26: =TRAMOS!A7 | C26: =TRAMOS!I7 | D26: =TRAMOS!D7 | E26: =TRAMOS!E7 | F26: =TRAMOS!F7 | G26: =IF($B$18<>"SI",0,IF($B$16=$B$17,ABS(INDEX($C$76:$AH$109,$B$14,6)-INDEX($C$76:$AH$109,$B$15,6)),INDEX($C$76:$AH$109,$B$14,6)+INDEX($C$76:$AH$109,$B$15,6))) | H26: =D26*$B$6*G26 | I26: =E26*(1-$B$6)*G26 | J26: =F26*G26
A27: =TRAMOS!J8 | B27: =TRAMOS!A8 | C27: =TRAMOS!I8 | D27: =TRAMOS!D8 | E27: =TRAMOS!E8 | F27: =TRAMOS!F8 | G27: =IF($B$18<>"SI",0,IF($B$16=$B$17,ABS(INDEX($C$76:$AH$109,$B$14,7)-INDEX($C$76:$AH$109,$B$15,7)),INDEX($C$76:$AH$109,$B$14,7)+INDEX($C$76:$AH$109,$B$15,7))) | H27: =D27*$B$6*G27 | I27: =E27*(1-$B$6)*G27 | J27: =F27*G27
A28: =TRAMOS!J9 | B28: =TRAMOS!A9 | C28: =TRAMOS!I9 | D28: =TRAMOS!D9 | E28: =TRAMOS!E9 | F28: =TRAMOS!F9 | G28: =IF($B$18<>"SI",0,IF($B$16=$B$17,ABS(INDEX($C$76:$AH$109,$B$14,8)-INDEX($C$76:$AH$109,$B$15,8)),INDEX($C$76:$AH$109,$B$14,8)+INDEX($C$76:$AH$109,$B$15,8))) | H28: =D28*$B$6*G28 | I28: =E28*(1-$B$6)*G28 | J28: =F28*G28
A29: =TRAMOS!J10 | B29: =TRAMOS!A10 | C29: =TRAMOS!I10 | D29: =TRAMOS!D10 | E29: =TRAMOS!E10 | F29: =TRAMOS!F10 | G29: =IF($B$18<>"SI",0,IF($B$16=$B$17,ABS(INDEX($C$76:$AH$109,$B$14,9)-INDEX($C$76:$AH$109,$B$15,9)),INDEX($C$76:$AH$109,$B$14,9)+INDEX($C$76:$AH$109,$B$15,9))) | H29: =D29*$B$6*G29 | I29: =E29*(1-$B$6)*G29 | J29: =F29*G29
A30: =TRAMOS!J11 | B30: =TRAMOS!A11 | C30: =TRAMOS!I11 | D30: =TRAMOS!D11 | E30: =TRAMOS!E11 | F30: =TRAMOS!F11 | G30: =IF($B$18<>"SI",0,IF($B$16=$B$17,ABS(INDEX($C$76:$AH$109,$B$14,10)-INDEX($C$76:$AH$109,$B$15,10)),INDEX($C$76:$AH$109,$B$14,10)+INDEX($C$76:$AH$109,$B$15,10))) | H30: =D30*$B$6*G30 | I30: =E30*(1-$B$6)*G30 | J30: =F30*G30
A31: =TRAMOS!J12 | B31: =TRAMOS!A12 | C31: =TRAMOS!I12 | D31: =TRAMOS!D12 | E31: =TRAMOS!E12 | F31: =TRAMOS!F12 | G31: =IF($B$18<>"SI",0,IF($B$16=$B$17,ABS(INDEX($C$76:$AH$109,$B$14,11)-INDEX($C$76:$AH$109,$B$15,11)),INDEX($C$76:$AH$109,$B$14,11)+INDEX($C$76:$AH$109,$B$15,11))) | H31: =D31*$B$6*G31 | I31: =E31*(1-$B$6)*G31 | J31: =F31*G31
A32: =TRAMOS!J13 | B32: =TRAMOS!A13 | C32: =TRAMOS!I13 | D32: =TRAMOS!D13 | E32: =TRAMOS!E13 | F32: =TRAMOS!F13 | G32: =IF($B$18<>"SI",0,IF($B$16=$B$17,ABS(INDEX($C$76:$AH$109,$B$14,12)-INDEX($C$76:$AH$109,$B$15,12)),INDEX($C$76:$AH$109,$B$14,12)+INDEX($C$76:$AH$109,$B$15,12))) | H32: =D32*$B$6*G32 | I32: =E32*(1-$B$6)*G32 | J32: =F32*G32
A33: =TRAMOS!J14 | B33: =TRAMOS!A14 | C33: =TRAMOS!I14 | D33: =TRAMOS!D14 | E33: =TRAMOS!E14 | F33: =TRAMOS!F14 | G33: =IF($B$18<>"SI",0,IF($B$16=$B$17,ABS(INDEX($C$76:$AH$109,$B$14,13)-INDEX($C$76:$AH$109,$B$15,13)),INDEX($C$76:$AH$109,$B$14,13)+INDEX($C$76:$AH$109,$B$15,13))) | H33: =D33*$B$6*G33 | I33: =E33*(1-$B$6)*G33 | J33: =F33*G33
A34: =TRAMOS!J15 | B34: =TRAMOS!A15 | C34: =TRAMOS!I15 | D34: =TRAMOS!D15 | E34: =TRAMOS!E15 | F34: =TRAMOS!F15 | G34: =IF($B$18<>"SI",0,IF($B$16=$B$17,ABS(INDEX($C$76:$AH$109,$B$14,14)-INDEX($C$76:$AH$109,$B$15,14)),INDEX($C$76:$AH$109,$B$14,14)+INDEX($C$76:$AH$109,$B$15,14))) | H34: =D34*$B$6*G34 | I34: =E34*(1-$B$6)*G34 | J34: =F34*G34
A35: =TRAMOS!J16 | B35: =TRAMOS!A16 | C35: =TRAMOS!I16 | D35: =TRAMOS!D16 | E35: =TRAMOS!E16 | F35: =TRAMOS!F16 | G35: =IF($B$18<>"SI",0,IF($B$16=$B$17,ABS(INDEX($C$76:$AH$109,$B$14,15)-INDEX($C$76:$AH$109,$B$15,15)),INDEX($C$76:$AH$109,$B$14,15)+INDEX($C$76:$AH$109,$B$15,15))) | H35: =D35*$B$6*G35 | I35: =E35*(1-$B$6)*G35 | J35: =F35*G35
A36: =TRAMOS!J17 | B36: =TRAMOS!A17 | C36: =TRAMOS!I17 | D36: =TRAMOS!D17 | E36: =TRAMOS!E17 | F36: =TRAMOS!F17 | G36: =IF($B$18<>"SI",0,IF($B$16=$B$17,ABS(INDEX($C$76:$AH$109,$B$14,16)-INDEX($C$76:$AH$109,$B$15,16)),INDEX($C$76:$AH$109,$B$14,16)+INDEX($C$76:$AH$109,$B$15,16))) | H36: =D36*$B$6*G36 | I36: =E36*(1-$B$6)*G36 | J36: =F36*G36
A37: =TRAMOS!J18 | B37: =TRAMOS!A18 | C37: =TRAMOS!I18 | D37: =TRAMOS!D18 | E37: =TRAMOS!E18 | F37: =TRAMOS!F18 | G37: =IF($B$18<>"SI",0,IF($B$16=$B$17,ABS(INDEX($C$76:$AH$109,$B$14,17)-INDEX($C$76:$AH$109,$B$15,17)),INDEX($C$76:$AH$109,$B$14,17)+INDEX($C$76:$AH$109,$B$15,17))) | H37: =D37*$B$6*G37 | I37: =E37*(1-$B$6)*G37 | J37: =F37*G37
A38: =TRAMOS!J19 | B38: =TRAMOS!A19 | C38: =TRAMOS!I19 | D38: =TRAMOS!D19 | E38: =TRAMOS!E19 | F38: =TRAMOS!F19 | G38: =IF($B$18<>"SI",0,IF($B$16=$B$17,ABS(INDEX($C$76:$AH$109,$B$14,18)-INDEX($C$76:$AH$109,$B$15,18)),INDEX($C$76:$AH$109,$B$14,18)+INDEX($C$76:$AH$109,$B$15,18))) | H38: =D38*$B$6*G38 | I38: =E38*(1-$B$6)*G38 | J38: =F38*G38
A39: =TRAMOS!J20 | B39: =TRAMOS!A20 | C39: =TRAMOS!I20 | D39: =TRAMOS!D20 | E39: =TRAMOS!E20 | F39: =TRAMOS!F20 | G39: =IF($B$18<>"SI",0,IF($B$16=$B$17,ABS(INDEX($C$76:$AH$109,$B$14,19)-INDEX($C$76:$AH$109,$B$15,19)),INDEX($C$76:$AH$109,$B$14,19)+INDEX($C$76:$AH$109,$B$15,19))) | H39: =D39*$B$6*G39 | I39: =E39*(1-$B$6)*G39 | J39: =F39*G39
A40: =TRAMOS!J21 | B40: =TRAMOS!A21 | C40: =TRAMOS!I21 | D40: =TRAMOS!D21 | E40: =TRAMOS!E21 | F40: =TRAMOS!F21 | G40: =IF($B$18<>"SI",0,IF($B$16=$B$17,ABS(INDEX($C$76:$AH$109,$B$14,20)-INDEX($C$76:$AH$109,$B$15,20)),INDEX($C$76:$AH$109,$B$14,20)+INDEX($C$76:$AH$109,$B$15,20))) | H40: =D40*$B$6*G40 | I40: =E40*(1-$B$6)*G40 | J40: =F40*G40
A41: =TRAMOS!J22 | B41: =TRAMOS!A22 | C41: =TRAMOS!I22 | D41: =TRAMOS!D22 | E41: =TRAMOS!E22 | F41: =TRAMOS!F22 | G41: =IF($B$18<>"SI",0,IF($B$16=$B$17,ABS(INDEX($C$76:$AH$109,$B$14,21)-INDEX($C$76:$AH$109,$B$15,21)),INDEX($C$76:$AH$109,$B$14,21)+INDEX($C$76:$AH$109,$B$15,21))) | H41: =D41*$B$6*G41 | I41: =E41*(1-$B$6)*G41 | J41: =F41*G41
A42: =TRAMOS!J23 | B42: =TRAMOS!A23 | C42: =TRAMOS!I23 | D42: =TRAMOS!D23 | E42: =TRAMOS!E23 | F42: =TRAMOS!F23 | G42: =IF($B$18<>"SI",0,IF($B$16=$B$17,ABS(INDEX($C$76:$AH$109,$B$14,22)-INDEX($C$76:$AH$109,$B$15,22)),INDEX($C$76:$AH$109,$B$14,22)+INDEX($C$76:$AH$109,$B$15,22))) | H42: =D42*$B$6*G42 | I42: =E42*(1-$B$6)*G42 | J42: =F42*G42
...

Sheet TRAMOS
A1: Ruta | B1: Origen | C1: Destino | D1: Fijos | E1: Variables | F1: AOM | G1: Cap Disp Flujo | H1: Cap D Contra Flujo | I1: Transportador | J1: Tramo | L1: Transportador | M1: Fijos | N1: Variables | O1: AOM
A2: Ballenas_tgi - Barranca | B2: Ballenas_tgi | C2: Barranca | D2: 3328.3778 | E2: 5041 | F2: 2435.5028 | I2: TGI | J2: 1 | L2: TGI | M2: 541.76111 | N2: 757 | O2: 160.90833
A3: Barranca - Sebastopol | B3: Barranca | C3: Sebastopol | D3: 1532.5611 | E3: 3381 | F3: 586.51944 | I3: TGI | J3: 2 | L3: PROMIGAS | M3: 815.331 | N3: 1195.386 | O3: 97
A4: Sebastopol - Transmetano | B4: Sebastopol | C4: Transmetano | D4: 1e-05 | E4: 1e-05 | F4: 0 | I4: TGI | J4: 3
A5: Transmetano - Donmatias | B5: Transmetano | C5: Donmatias | D5: 1e-05 | E5: 1e-05 | F5: 0 | I5: TGI | J5: 4
A6: Donmatias - Barbosa | B6: Donmatias | C6: Barbosa | D6: 1e-05 | E6: 1e-05 | F6: 0 | I6: TGI | J6: 5
A7: Barbosa - Girardota | B7: Barbosa | C7: Girardota | D7: 1e-05 | E7: 1e-05 | F7: 0 | I7: TGI | J7: 6
A8: Girardota - Bello | B8: Girardota | C8: Bello | D8: 1e-05 | E8: 1e-05 | F8: 0 | I8: TGI | J8: 7
A9: Bello - Medellin | B9: Bello | C9: Medellin | D9: 5254.2953 | E9: 6590 | F9: 839.97534 | I9: TGI | J9: 8
A10: Sebastopol - Vasconia | B10: Sebastopol | C10: Vasconia | D10: 625.73889 | E10: 1868 | F10: 168.82778 | I10: TGI | J10: 9
A11: Vasconia - Mariquita | B11: Vasconia | C11: Mariquita | D11: 1489.125 | E11: 2208 | F11: 439.37778 | I11: TGI | J11: 10
A12: Mariquita - Gualanday | B12: Mariquita | C12: Gualanday | D12: 5177.6833 | E12: 5420 | F12: 1079.8444 | I12: TGI | J12: 11
A13: Gualanday - Neiva | B13: Gualanday | C13: Neiva | D13: 18816.314 | E13: 20660 | F13: 2600.4917 | I13: TGI | J13: 12
A14: Gualanday - Montañuelo | B14: Gualanday | C14: Montañuelo | D14: 0 | E14: 0 | F14: 0 | I14: TGI | J14: 13
A15: Mariquita - Pereira | B15: Mariquita | C15: Pereira | D15: 1869.8083 | E15: 2960 | F15: 1506.375 | I15: TGI | J15: 14
... A33: Sincelejo - Jobo | B33: Sincelejo | C33: Jobo | D33: 1675.082 | E33: 1769.096 | F33: 956 | I33: PROMIGAS | J33: 32
A35: Nota: 'Cap Disp Flujo' y 'Cap D Contra Flujo' se dejan disponibles para capacidad contratada/disponible; no forman parte del calculo de tarifa unitaria.

Sheet listas
A1: Origenes | B1: Destinos | D1: Opcion %CF | E1: Valor %CF | G1: Opcion Impuesto Local | H1: Valor Impuesto
A2: Acopi | B2: Acopi | D2: 100% Fijo / 0% Variable | E2: 1 | G2: 0% - Sin impuesto local | H2: 0
A3: Apiay | B3: Apiay | D3: 85% Fijo / 15% Variable | E3: 0.85 | G3: 2% - Impuesto especial municipal | H3: 0.02
A4: Armenia | B4: Armenia | D4: 70% Fijo / 30% Variable | E4: 0.7 | G4: 6% - Impuesto especial municipal | H4: 0.06
A5: Ballenas_prom | B5: Ballenas_prom | D5: 50% Fijo / 50% Variable | E5: 0.5
A6: Ballenas_tgi | B6: Ballenas_tgi | D6: 30% Fijo / 70% Variable | E6: 0.3
A7: Barbosa | B7: Barbosa | D7: 15% Fijo / 85% Variable | E7: 0.15
A8: Barranca | B8: Barranca | D8: 0% Fijo / 100% Variable | E8: 0
A9: Barranquilla | B9: Barranquilla
A10: Bello | B10: Bello
A11: Cali | B11: Cali
A12: Cartagena | B12: Cartagena
A13: Cogua | B13: Cogua
A14: Cusiana | B14: Cusiana
A15: Donmatias | B15: Donmatias
A16: Girardota | B16: Girardota
A17: Gualanday | B17: Gualanday
A18: Jobo | B18: Jobo
A19: La Belleza | B19: La Belleza
A20: La Creciente | B20: La Creciente
... A35: Villavicencio | B35: Villavicencio
